Workbook

Sheet Receitas
B1: Ingredientes | C1: Quantidade | D1: Preco
A2: Estrogonof de Frango | B2: Alho | C2: 10 | D2: =_xlfn.MINIFS(Precos!$E:$E, Precos!$A:$A, B2)/1000*C2 -> 0.198
B3: Arroz | C3: 70 | D3: =_xlfn.MINIFS(Precos!$E:$E, Precos!$A:$A, B3)/1000*C3 -> 0.2996
B4: Batata Doce | C4: 80 | D4: =_xlfn.MINIFS(Precos!$E:$E, Precos!$A:$A, B4)/1000*C4 -> 0.2384
B5: Cebola | C5: 60 | D5: =_xlfn.MINIFS(Precos!$E:$E, Precos!$A:$A, B5)/1000*C5 -> 0.1188
B6: Frango | C6: 140 | D6: =_xlfn.MINIFS(Precos!$E:$E, Precos!$A:$A, B6)/1000*C6 -> 2.7972
B7: Leite | C7: 40 | D7: =_xlfn.MINIFS(Precos!$E:$E, Precos!$A:$A, B7)/1000*C7 -> 0.1712
B8: Manteiga | C8: 8 | D8: =_xlfn.MINIFS(Precos!$E:$E, Precos!$A:$A, B8)/200*C8 -> 0.54 | E8: Total
B9: Repolho | C9: 80 | D9: =_xlfn.MINIFS(Precos!$E:$E, Precos!$A:$A, B9)/1000*C9 -> 0.2384 | E9: =SUM(D1:D9) -> 4.6016
A10: 1
A11: Estrogonof de Carne | B11: Alho | C11: 10 | D11: =_xlfn.MINIFS(Precos!$E:$E, Precos!$A:$A, B11)/1000*C11 -> 0.198
B12: Arroz | C12: 70 | D12: =_xlfn.MINIFS(Precos!$E:$E, Precos!$A:$A, B12)/1000*C12 -> 0.2996
B13: Batata Doce | C13: 80 | D13: =_xlfn.MINIFS(Precos!$E:$E, Precos!$A:$A, B13)/1000*C13 -> 0.2384
B14: Cebola | C14: 60 | D14: =_xlfn.MINIFS(Precos!$E:$E, Precos!$A:$A, B14)/1000*C14 -> 0.1188
B15: Carne | C15: 140 | D15: =_xlfn.MINIFS(Precos!$E:$E, Precos!$A:$A, B15)/1000*C15 -> 3.626
B16: Leite | C16: 40 | D16: =_xlfn.MINIFS(Precos!$E:$E, Precos!$A:$A, B16)/1000*C16 -> 0.1712
B17: Manteiga | C17: 8 | D17: =_xlfn.MINIFS(Precos!$E:$E, Precos!$A:$A, B17)/1000*C17 -> 0.108 | E17: Total
B18: Repolho | C18: 80 | D18: =_xlfn.MINIFS(Precos!$E:$E, Precos!$A:$A, B18)/1000*C18 -> 0.2384 | E18: =SUM(D11:D18) -> 4.9984
A19: 1
A20: Estrogonof de Cogumelos | B20: Alho | C20: 10 | D20: =_xlfn.MINIFS(Precos!$E:$E, Precos!$A:$A, B20)/1000*C20 -> 0.198
B21: Arroz | C21: 70 | D21: =_xlfn.MINIFS(Precos!$E:$E, Precos!$A:$A, B21)/1000*C21 -> 0.2996
B22: Batata Doce | C22: 80 | D22: =_xlfn.MINIFS(Precos!$E:$E, Precos!$A:$A, B22)/1000*C22 -> 0.2384
B23: Cebola | C23: 60 | D23: =_xlfn.MINIFS(Precos!$E:$E, Precos!$A:$A, B23)/1000*C23 -> 0.1188
B24: Cogumelos | C24: 140 | D24: =_xlfn.MINIFS(Precos!$E:$E, Precos!$A:$A, B24)/1000*C24 -> 0
B25: Leite | C25: 40 | D25: =_xlfn.MINIFS(Precos!$E:$E, Precos!$A:$A, B25)/1000*C25 -> 0.1712
B26: Manteiga | C26: 8 | D26: =_xlfn.MINIFS(Precos!$E:$E, Precos!$A:$A, B26)/200*C26 -> 0.54 | E26: Total
B27: Repolho | C27: 80 | D27: =_xlfn.MINIFS(Precos!$E:$E, Precos!$A:$A, B27)/1000*C27 -> 0.2384 | E27: =SUM(D20:D27) -> 1.8044
A28: 1
A29: Tradicional de Frango | B29: Alho | C29: 13 | D29: =_xlfn.MINIFS(Precos!$E:$E, Precos!$A:$A, B29)/1000*C29 -> 0.2574
B30: Arroz | C30: 70 | D30: =_xlfn.MINIFS(Precos!$E:$E, Precos!$A:$A, B30)/1000*C30 -> 0.2996
B31: Brocolis | C31: 80 | D31: =_xlfn.MINIFS(Precos!$E:$E, Precos!$A:$A, B31)/1000*C31 -> 0.52
B32: Cebola | C32: 60 | D32: =_xlfn.MINIFS(Precos!$E:$E, Precos!$A:$A, B32)/1000*C32 -> 0.1188
B33: Couve Flor | C33: 80 | D33: =_xlfn.MINIFS(Precos!$E:$E, Precos!$A:$A, B33)/1000*C33 -> 0
B34: Frango | C34: 140 | D34: =_xlfn.MINIFS(Precos!$E:$E, Precos!$A:$A, B34)/1000*C34 -> 2.7972 | E34: Total
B35: Mussarela | C35: 20 | D35: =_xlfn.MINIFS(Precos!$E:$E, Precos!$A:$A, B35)/1000*C35 -> 0.6 | E35: =SUM(D29:D35) -> 4.593
A36: 1
A37: Tradicional de Carne | B37: Alho | C37: 13 | D37: =_xlfn.MINIFS(Precos!$E:$E, Precos!$A:$A, B37)/1000*C37 -> 0.2574
B38: Arroz | C38: 70 | D38: =_xlfn.MINIFS(Precos!$E:$E, Precos!$A:$A, B38)/1000*C38 -> 0.2996
B39: Brocolis | C39: 80 | D39: =_xlfn.MINIFS(Precos!$E:$E, Precos!$A:$A, B39)/1000*C39 -> 0.52
B40: Cebola | C40: 60 | D40: =_xlfn.MINIFS(Precos!$E:$E, Precos!$A:$A, B40)/1000*C40 -> 0.1188
...

Sheet Precos
A1: Ingrediente | B1: Mar Vermelho | C1: Assaí | D1: Mineirão | E1: Menor Preço
A2: Abobrinha | B2: 5.49 | C2: 6.99 | D2: 5.98 | E2: =MIN($B2:$D2) -> 5.49
A3: Alho | B3: 32 | C3: 25.99 | D3: 19.8 | E3: =MIN($B3:$D3) -> 19.8
A4: Arroz | B4: 4.75 | C4: 5 | D4: 4.28 | E4: =MIN($B4:$D4) -> 4.28
A5: Batata Doce | B5: 3.98 | C5: 3.98 | D5: 2.98 | E5: =MIN($B5:$D5) -> 2.98
A6: Brocolis | B6: 6.5 | E6: =MIN($B6:$D6) -> 6.5
A7: Carne | B7: 34.99 | C7: 25.9 | D7: 34.99 | E7: =MIN($B7:$D7) -> 25.9
A8: Cebola | B8: 2.6 | C8: 2.79 | D8: 1.98 | E8: =MIN($B8:$D8) -> 1.98
A9: Cenoura | B9: 4.59 | C9: 4.79 | D9: 3.98 | E9: =MIN($B9:$D9) -> 3.98
A10: Couve Flor | E10: =MIN($B10:$D10) -> 0
A11: Extrato de Tomate | B11: 3.99 | C11: 4.19 | D11: 2.99 | E11: =MIN($B11:$D11) -> 2.99
A12: Farinha | D12: 4 | E12: =MIN($B12:$D12) -> 4
A13: Frango | B13: 23.98 | C13: 23.99 | D13: 19.98 | E13: =MIN($B13:$D13) -> 19.98
A14: Leite | B14: 4.49 | C14: 6 | D14: 4.28 | E14: =MIN($B14:$D14) -> 4.28
A15: Linguica | B15: 17 | C15: 17.9 | D15: 17.99 | E15: =MIN($B15:$D15) -> 17
A16: Macarrao | C16: 4.09 | E16: =MIN($B16:$D16) -> 4.09
A17: Manteiga | B17: 13.5 | C17: 13.6 | E17: =MIN($B17:$D17) -> 13.5
A18: Molho de Tomate | B18: 2.89 | C18: 2.29 | E18: =MIN($B18:$D18) -> 2.29
A19: Mussarela | B19: 30 | C19: 49.5 | E19: =MIN($B19:$D19) -> 30
A20: Oleo | B20: 8.29 | C20: 8.65 | E20: =MIN($B20:$D20) -> 8.29
A21: Repolho | B21: 4.98 | C21: 4 | D21: 2.98 | E21: =MIN($B21:$D21) -> 2.98

Sheet ListaQuantidade
A1: Ingreditentes | B1: OndeComprar | C1: Quantidade | D1: Preco
A2: Abobrinha | B2: =_xlfn.XLOOKUP(Precos!E2, Precos!B2:D2, Precos!$B$1:$D$1) -> Mar Vermelho | C2: =SUMIF(Receitas!$B2:$B100, A2, Receitas!$C2:$C100) -> 150 | D2: =Precos!E2*C2/1000 -> 0.8235
A3: Alho | B3: =_xlfn.XLOOKUP(Precos!E3, Precos!B3:D3, Precos!$B$1:$D$1) -> Mineirão | C3: =SUMIF(Receitas!$B3:$B101, A3, Receitas!$C3:$C101) -> 89 | D3: =Precos!E3*C3/1000 -> 1.7622
A4: Arroz | B4: =_xlfn.XLOOKUP(Precos!E4, Precos!B4:D4, Precos!$B$1:$D$1) -> Mineirão | C4: =SUMIF(Receitas!$B4:$B102, A4, Receitas!$C4:$C102) -> 350 | D4: =Precos!E4*IF(C4>1000,1*C4/1000,1) -> 4.28
A5: Batata Doce | B5: =_xlfn.XLOOKUP(Precos!E5, Precos!B5:D5, Precos!$B$1:$D$1) -> Mineirão | C5: =SUMIF(Receitas!$B5:$B103, A5, Receitas!$C5:$C103) -> 160 | D5: =Precos!E5*C5/1000 -> 0.4768
A6: Brocolis | B6: =_xlfn.XLOOKUP(Precos!E6, Precos!B6:D6, Precos!$B$1:$D$1) -> Mar Vermelho | C6: =SUMIF(Receitas!$B6:$B104, A6, Receitas!$C6:$C104) -> 240 | D6: =Precos!E6*C6/500 -> 3.12
A7: Carne | B7: =_xlfn.XLOOKUP(Precos!E7, Precos!B7:D7, Precos!$B$1:$D$1) -> Assaí | C7: =SUMIF(Receitas!$B7:$B105, A7, Receitas!$C7:$C105) -> 380 | D7: =Precos!E7*C7/1000 -> 9.842
A8: Cebola | B8: =_xlfn.XLOOKUP(Precos!E8, Precos!B8:D8, Precos!$B$1:$D$1) -> Mineirão | C8: =SUMIF(Receitas!$B8:$B106, A8, Receitas!$C8:$C106) -> 390 | D8: =Precos!E8*C8/1000 -> 0.7722
A9: Cenoura | B9: =_xlfn.XLOOKUP(Precos!E9, Precos!B9:D9, Precos!$B$1:$D$1) -> Mineirão | C9: =SUMIF(Receitas!$B9:$B107, A9, Receitas!$C9:$C107) -> 150 | D9: =Precos!E9*C9/1000 -> 0.597
A10: Couve Flor | B10: =_xlfn.XLOOKUP(Precos!E10, Precos!B10:D10, Precos!$B$1:$D$1) -> #N/A | C10: =SUMIF(Receitas!$B10:$B108, A10, Receitas!$C10:$C108) -> 240 | D10: =Precos!E10*C10/1000 -> 0
A11: Extrato de Tomate | B11: =_xlfn.XLOOKUP(Precos!E11, Precos!B11:D11, Precos!$B$1:$D$1) -> Mineirão | C11: =SUMIF(Receitas!$B11:$B109, A11, Receitas!$C11:$C109) -> 30 | D11: =Precos!E11*IF(C11>200,1*C11/200,1) -> 2.99
A12: Farinha | B12: =_xlfn.XLOOKUP(Precos!E12, Precos!B12:D12, Precos!$B$1:$D$1) -> Mineirão | C12: =SUMIF(Receitas!$B12:$B110, A12, Receitas!$C12:$C110) -> 0 | D12: =Precos!E12*IF(C12>1000,1*C12/1000,1) -> 4
A13: Frango | B13: =_xlfn.XLOOKUP(Precos!E13, Precos!B13:D13, Precos!$B$1:$D$1) -> Mineirão | C13: =SUMIF(Receitas!$B13:$B111, A13, Receitas!$C13:$C111) -> 140 | D13: =Precos!E13*C13/1000 -> 2.7972
A14: Leite | B14: =_xlfn.XLOOKUP(Precos!E14, Precos!B14:D14, Precos!$B$1:$D$1) -> Mineirão | C14: =SUMIF(Receitas!$B14:$B112, A14, Receitas!$C14:$C112) -> 80 | D14: =Precos!E14*IF(C14>1000,1*C14/1000,1) -> 4.28
A15: Linguica | B15: =_xlfn.XLOOKUP(Precos!E15, Precos!B15:D15, Precos!$B$1:$D$1) -> Mar Vermelho | C15: =SUMIF(Receitas!$B15:$B113, A15, Receitas!$C15:$C113) -> 100 | D15: =Precos!E15*C15/1000 -> 1.7
A16: Macarrao | B16: =_xlfn.XLOOKUP(Precos!E16, Precos!B16:D16, Precos!$B$1:$D$1) -> Assaí | C16: =SUMIF(Receitas!$B16:$B114, A16, Receitas!$C16:$C114) -> 270 | D16: =Precos!E16*IF(C16>1000,1*C16/1000,1) -> 4.09
A17: Manteiga | B17: =_xlfn.XLOOKUP(Precos!E17, Precos!B17:D17, Precos!$B$1:$D$1) -> Mar Vermelho | C17: =SUMIF(Receitas!$B17:$B115, A17, Receitas!$C17:$C115) -> 46 | D17: =Precos!E17*IF(C17>200,1*C17/200,1) -> 13.5
A18: Molho de Tomate | B18: =_xlfn.XLOOKUP(Precos!E18, Precos!B18:D18, Precos!$B$1:$D$1) -> Assaí | C18: =SUMIF(Receitas!$B18:$B116, A18, Receitas!$C18:$C116) -> 150 | D18: =Precos!E18*IF(C18>500,1*C18/500,1) -> 2.29
A19: Mussarela | B19: =_xlfn.XLOOKUP(Precos!E19, Precos!B19:D19, Precos!$B$1:$D$1) -> Mar Vermelho | C19: =SUMIF(Receitas!$B19:$B117, A19, Receitas!$C19:$C117) -> 60 | D19: =Precos!E19*C19/1000 -> 1.8
A20: Oleo | B20: =_xlfn.XLOOKUP(Precos!E20, Precos!B20:D20, Precos!$B$1:$D$1) -> Mar Vermelho | C20: =SUMIF(Receitas!$B20:$B118, A20, Receitas!$C20:$C118) -> 0 | D20: =Precos!E20*IF(C20>1000,1*C20/1000,1) -> 8.29
A21: Repolho | B21: =_xlfn.XLOOKUP(Precos!E21, Precos!B21:D21, Precos!$B$1:$D$1) -> Mineirão | C21: =SUMIF(Receitas!$B21:$B119, A21, Receitas!$C21:$C119) -> 80 | D21: =Precos!E21*C21/1000 -> 0.2384
D22: =SUM(D2:D21) -> 67.6493 | E22: Total
